Logging to ./experiments/log/
creating model...
Traceback (most recent call last):
  File "/home/labuser/AT_DDPM/scripts/AT_test.py", line 64, in <module>
    main(run)
  File "/home/labuser/AT_DDPM/scripts/AT_test.py", line 48, in main
    diffusion_test(val_data,model,diffusion, './results/', run , 'test', skip_timesteps=40, iter=0)
  File "/home/labuser/AT_DDPM/guided_diffusion/test_diff.py", line 48, in diffusion_test
    sample = diffusion.p_sample_loop(
  File "/home/labuser/AT_DDPM/guided_diffusion/gaussian_diffusion.py", line 459, in p_sample_loop
    for sample in self.p_sample_loop_progressive(
  File "/home/labuser/AT_DDPM/guided_diffusion/gaussian_diffusion.py", line 511, in p_sample_loop_progressive
    out = self.p_sample(
  File "/home/labuser/AT_DDPM/guided_diffusion/gaussian_diffusion.py", line 408, in p_sample
    out = self.p_mean_variance(
  File "/home/labuser/AT_DDPM/guided_diffusion/respace.py", line 91, in p_mean_variance
    return super().p_mean_variance(self._wrap_model(model), *args, **kwargs)
  File "/home/labuser/AT_DDPM/guided_diffusion/gaussian_diffusion.py", line 252, in p_mean_variance
    model_output, model_var_values = th.split(model_output, C, dim=1)
ValueError: not enough values to unpack (expected 2, got 1)